<?xml version="1.0"?>
<robot name="robot_zero" xmlns:xacro="http://www.ros.org/wiki/xacro" >

    <xacro:include filename="inertial_macros.xacro"/>


    <xacro:property name="chassis_length" value="0.420"/>
    <xacro:property name="chassis_width" value="0.340"/>
    <xacro:property name="chassis_height" value="0.20"/>
    <xacro:property name="chassis_mass" value="3.0"/>
    <xacro:property name="wheel_radius" value="0.0635"/>
    <xacro:property name="wheel_thickness" value="0.025"/>
    <xacro:property name="wheel_mass" value="0.05"/>
    <xacro:property name="wheel_offset_x" value="0.1"/>  
    <xacro:property name="wheel_offset_y" value="0.1775"/>
    <xacro:property name="wheel_offset_z" value="0.046"/> 
    <xacro:property name="caster_wheel_radius" value="0.02"/>
    <xacro:property name="caster_wheel_mass" value="0.01"/>
    <xacro:property name="caster_wheel_offset_x" value="0.360"/>
    <xacro:property name="caster_wheel_offset_z" value="${wheel_offset_z - wheel_radius + caster_wheel_radius}"/>

    <material name="white">
        <color rgba="1 1 1 1" />
    </material>

    <material name="orange">
        <color rgba="1 0.3 0.1 1"/>
    </material>

    <material name="blue">
        <color rgba="0.2 0.2 1 1"/>
    </material>

    <material name="black">
        <color rgba="0 0 0 1"/>
    </material>

    <material name="red">
        <color rgba="1 0 0 1"/>
    </material>

    <!-- BASE LINK -->

    <link name="base_link">

    </link>

    <!-- BASE_FOOTPRINT LINK -->

    <joint name="base_footprint_joint" type="fixed">
        <parent link="base_link"/>
        <child link="base_footprint"/>
        <origin xyz="-0.11 0 ${wheel_offset_z}" rpy="0 0 0"/>
    </joint>

    <link name="base_footprint">
    </link>


    <!-- CHASSIS LINK -->

    <joint name="chassis_joint" type="fixed">
        <parent link="base_link"/>
        <child link="chassis"/>
        <origin xyz="${-wheel_offset_x} 0 ${-wheel_offset_z}"/>
    </joint>

    <link name="chassis">
        <visual>
            <origin xyz="${chassis_length/2 + 0.006} 0 ${chassis_height/2}" rpy="0 0 1.5708"/>
            <geometry>
                <!-- <box size="${chassis_length} ${chassis_width} ${chassis_height}"/> -->
                 <mesh filename="file:///$(find robot_zero)/meshes/Chassis.stl" scale="1 1 1"/>
            </geometry>
            <material name="orange"/>
        </visual>
        <collision>
            <origin xyz="${chassis_length/2} 0 ${chassis_height/2}"/>
            <geometry>
                <box size="${chassis_length} ${chassis_width} ${chassis_height}"/>
            </geometry>
        </collision>
        <xacro:inertial_box mass="0.5" x="${chassis_length}" y="${chassis_width}" z="${chassis_height}">
            <origin xyz="${chassis_length/2} 0 ${chassis_height/2}" rpy="0 0 0"/>
        </xacro:inertial_box>
    </link>

    <gazebo reference="chassis">
        <material>Gazebo/Orange</material>
    </gazebo>

    <!-- LEFT WHEEL LINK -->

    <joint name="left_wheel_joint" type="continuous">
        <parent link="base_link"/>
        <child link="left_wheel"/>
        <origin xyz="0 ${wheel_offset_y} 0" rpy="-${pi/2} 0 0" />
        <axis xyz="0 0 1"/>
    </joint>

    <link name="left_wheel">
        <visual>
            <geometry>
                <cylinder radius="${wheel_radius}" length="${wheel_thickness}"/>
            </geometry>
            <material name="blue"/>
        </visual>
        <collision>
            <geometry>
                <sphere radius="${wheel_radius}"/>
            </geometry>
        </collision>
        <xacro:inertial_cylinder mass="${wheel_mass}" length="${wheel_thickness}" radius="${wheel_radius}">
            <origin xyz="0 0 0" rpy="0 0 0"/>
        </xacro:inertial_cylinder>
    </link>

    <gazebo reference="left_wheel">
        <material>Gazebo/Blue</material>
    </gazebo>




    <!-- RIGHT WHEEL LINK -->

    <joint name="right_wheel_joint" type="continuous">
        <parent link="base_link"/>
        <child link="right_wheel"/>
        <origin xyz="0 ${-wheel_offset_y} 0" rpy="${pi/2} 0 0" />
        <axis xyz="0 0 -1"/>
    </joint>

    <link name="right_wheel">
        <visual>
            <geometry>
                <cylinder radius="${wheel_radius}" length="${wheel_thickness}"/>
            </geometry>
            <material name="blue"/>
        </visual>
        <collision>
            <geometry>
                <sphere radius="${wheel_radius}"/>
            </geometry>
        </collision>
        <xacro:inertial_cylinder mass="${wheel_mass}" length="${wheel_thickness}" radius="${wheel_radius}">
            <origin xyz="0 0 0" rpy="0 0 0"/>
        </xacro:inertial_cylinder>
    </link>

    <gazebo reference="right_wheel">
        <material>Gazebo/Blue</material>
    </gazebo>


    <!-- CASTER WHEEL LINK -->

    <joint name="caster_wheel_joint" type="fixed">
        <parent link="chassis"/>
        <child link="caster_wheel"/>
        <origin xyz="${caster_wheel_offset_x} 0 ${caster_wheel_offset_z}"/>
    </joint>


    <link name="caster_wheel">
        <visual>
            <geometry>
                <sphere radius="${caster_wheel_radius}"/>
            </geometry>
            <material name="white"/>
        </visual>
        <collision>
            <geometry>
                <sphere radius="${caster_wheel_radius}"/>
            </geometry>
        </collision>
        <xacro:inertial_sphere mass="${caster_wheel_mass}" radius="${caster_wheel_radius}">
            <origin xyz="0 0 0" rpy="0 0 0"/>
        </xacro:inertial_sphere>
    </link>

    <gazebo reference="caster_wheel">
        <material>Gazebo/White</material>
        <mu1 value="0.001"/>
        <mu2 value="0.001"/>
    </gazebo>

    <!-- CAMERA LINK -->
    <joint name="camera_joint" type="fixed">
        <parent link="base_link"/>
        <child link="camera_link"/>
        <origin xyz="0 0 0.2" rpy="0 0 0"/>
    </joint>

    <link name="camera_link">
        <visual>
            <geometry>
            <box size="0.05 0.05 0.05"/>
            </geometry>
        </visual>

        <collision>
            <geometry>
            <box size="0.05 0.05 0.05"/>
            </geometry>
        </collision>

        <inertial>
            <mass value="0.1"/>
            <inertia ixx="0.0001" iyy="0.0001" izz="0.0001"
                    ixy="0" ixz="0" iyz="0"/>
        </inertial>
    </link>


    <gazebo reference="camera_link">
    <sensor type="depth" name="realsense">
        <update_rate>30.0</update_rate>

        <camera>
        <horizontal_fov>1.047</horizontal_fov>
        <image>
            <width>640</width>
            <height>480</height>
            <format>R8G8B8</format>
        </image>
        <clip>
            <near>0.1</near>
            <far>10.0</far>
        </clip>
        </camera>

        <plugin name="realsense_plugin" filename="libgazebo_ros_camera.so">
        <ros>
            <namespace>/</namespace>
        </ros>
        <camera_name>camera</camera_name>
        <frame_name>camera_link</frame_name>
        </plugin>

    </sensor>
    </gazebo>

    
    <!-- <gazebo>
    <plugin name="diff_drive" filename="libgazebo_ros_diff_drive.so">
        <ros>
        <namespace>/</namespace>
        </ros>

        <left_joint>left_wheel_joint</left_joint>
        <right_joint>right_wheel_joint</right_joint>

        <wheel_separation>0.355</wheel_separation>
        <wheel_diameter>0.127</wheel_diameter>

        <command_topic>cmd_vel</command_topic>
        <odometry_topic>odom</odometry_topic>

        <odometry_frame>odom</odometry_frame>
        <robot_base_frame>base_link</robot_base_frame>

        <publish_odom>true</publish_odom>
        <publish_odom_tf>true</publish_odom_tf>
    </plugin>
    </gazebo> -->   
   
    // GazeboSystem  ← hardware interface, convert cmd velocity to joint movements
    <ros2_control name="RobotZeroSystem" type="system">
        // Driver 
        <hardware>
            <plugin>gazebo_ros2_control/GazeboSystem</plugin>
        </hardware>

        <joint name="left_wheel_joint">
            <command_interface name="velocity"/>
            <state_interface name="velocity"/>
            <state_interface name="position"/>
        </joint>

        <joint name="right_wheel_joint">
            <command_interface name="velocity"/>
            <state_interface name="velocity"/>
            <state_interface name="position"/>
        </joint>

    </ros2_control>

    // loads controller_manager + YAML
    <gazebo>
        <plugin name="gazebo_ros2_control" filename="libgazebo_ros2_control.so">
            <parameters>/root/ros2_ws/src/robot_zero/config/controllers.yaml</parameters>
        </plugin>
    </gazebo>

</robot>